Workbook

Sheet Pivot
A1: Facility Name | B1: (All)
A2: County | B2: (All)
A3: Health Facility Planning Area (HFPA) | B3: (All)
A4: Type of Care | B4: (All)
A5: License Category | B5: (All)
A6: Type of Control | B6: (All)
A7: Bed Size | B7: (All)
A8: Residential Care | B8: (All)
A10: Data | B10: Total
A11: Sum of FAC_NO | B11: 221944919376
A12: Count of FAC_NO | B12: 1076
A13: Sum of BED_AVG | B13: 108060
A14: Sum of BED_END | B14: 108060
A15: Sum of DAY_TOTL | B15: 34576964
A16: Sum of Licensed Bed Days | B16: 39061329
A17: Sum of ADMITS | B17: 348227
A18: Sum of DISCHS | B18: 346685
A19: Sum of DAYS_MCARE_FFS2 | B19: 5656431
A20: Sum of DAYS_MCARE_MGD2 | B20: 2216758
A21: Sum of DAYS_MCAL_FFS2 | B21: 3266548
A22: Sum of DAYS_MCAL_MGD2 | B22: 19260667
... A39: Sum of GR_AN_MCAL_FFS_IP2 | B39: 90681588
A40: Sum of GR_AN_MCAL_FFS_OP
A41: Sum of GR_AN_MCAL_MGD_IP | B41: 416072176
A42: Sum of GR_AN_MCAL_MGD_OP
A43: Sum of GR_AN_CC_FFS_IP | B43: 165372780
A44: Sum of GR_AN_CC_FFS_OP | B44: 80693
A45: Sum of GR_AN_CC_MGD_IP | B45: 328764116
A46: Sum of GR_AN_CC_MGD_OP2 | B46: 115064
A47: Sum of GR_AN_SELF_IP | B47: 26125257
A48: Sum of GR_AN_OTH_IP | B48: 69426448
A49: Sum of GR_AN_SELF_OP | B49: 64598
A50: Sum of GR_AN_OTH_OP | B50: 36839
A51: Sum of DAY_SN | B51: 32708093
A52: Sum of DAY_IC | B52: 11531
A53: Sum of DAY_MD | B53: 769034
A54: Sum of DAY_DD | B54: 138892
... A56: Sum of DAY_SUBPED | B56: 44633
A57: Sum of DAY_TIC
A58: Sum of DAY_HOSPIC
...

Sheet Profile
A1: Profile Characteristics | E1: =IF($B$2=1,"Individual Facility Characteristics","Type of Control") -> Type of Control
A2: No. of Facilities | B2: =Pivot!B12 -> 1076 | E2: =IF($B$2=1,"Facility Name","Investor Owned:") -> Investor Owned: | F2: =IF($B$2=1,VLOOKUP($H$6,Data!$A$1:$IS$1061,2,FALSE),Pivot!B172) -> 980
A3: Facility Name | B3: =Pivot!B1 -> (All) | E3: =IF($B$2=1,"Address","Not-For-Profit:") -> Not-For-Profit: | F3: =IF($B$2=1,VLOOKUP($H$6,Data!$A$1:$IS$1061,14,FALSE),Pivot!B173) -> 92
A4: County | B4: =Pivot!B2 -> (All) | E4: =IF($B$2=1,"City","Governmental:") -> Governmental: | F4: =IF($B$2=1,VLOOKUP($H$6,Data!$A$1:$IS$1061,15,FALSE),Pivot!B174) -> 4
A5: HFPA | B5: =Pivot!B3 -> (All) | E5: =IF($B$2=1,"State","") | F5: =IF($B$2=1,"CALIFORNIA","") | G5: =IF($B$2=1,"","Facility Size") -> Facility Size
A6: Type of Care | B6: =Pivot!B4 -> (All) | E6: =IF($B$2=1,"Zip","") | F6: =IF($B$2=1,VLOOKUP($H$6,Data!$A$1:$IS$1061,16,FALSE),"") | G6: =IF($B$2=1,"OSHPD ID","1 - 59 Beds:") -> 1 - 59 Beds: | H6: =IF($B$2=1,Pivot!B11,Pivot!B175) -> 265
A7: License Category | B7: =Pivot!B5 -> (All) | E7: =IF($B$2=1,"Phone #","") | F7: =IF($B$2=1,VLOOKUP($H$6,Data!$A$1:$IS$1061,13,FALSE),"") | G7: =IF($B$2=1,"Medi-Cal Provider #","60 - 99 Beds:") -> 60 - 99 Beds: | H7: =IF($B$2=1,IF(VLOOKUP($H$6,Data!$A$1:$IS$2000,17,FALSE)=0,"",VLOOKUP($H$6,Data!$A$1:$IS$2000,17,FALSE)),Pivot!B176) -> 457
A8: Licensed Bed Size | B8: =Pivot!B6 -> (All) | E8: =IF($B$2=1,"","Type of Care*") -> Type of Care* | G8: =IF($B$2=1,"","100 + Beds:") -> 100 + Beds: | H8: =IF($B$2=1,"",GETPIVOTDATA("Sum of 100+ Beds",Pivot!$A$10)) -> 354
A9: Residential Care | B9: =Pivot!B7 -> (All) | E9: =IF($B$2=1,"County","Skilled Nursing:") -> Skilled Nursing: | F9: =IF($B$2=1,VLOOKUP($H$6,Data!$A$1:$IS$2000,8,FALSE),Pivot!B178) -> 1049 | G9: =IF($B$2=1,"Report Period Begin","") | H9: =IF($B$2=1,VLOOKUP($H$6,Data!$A$1:$IS$2000,3,FALSE),"")
E10: =IF($B$2=1,"Type of Care","Intermediate Care:") -> Intermediate Care: | F10: =IF($B$2=1,VLOOKUP($H$6,Data!$A$1:$IS$1061,37,FALSE),Pivot!B179) -> 1 | G10: =IF($B$2=1,"Report Period End","") | H10: =IF($B$2=1,VLOOKUP($H$6,Data!$A$1:$IS$2000,4,FALSE),"")
E11: =IF($B$2=1,"License Category","Mentally Disordered:") -> Mentally Disordered: | F11: =IF($B$2=1,VLOOKUP($H$6,Data!$A$1:$IS$1061,9,FALSE),Pivot!B180) -> 23 | G11: =IF($B$2=1,"Days in Period","") | H11: =IF($B$2=1,VLOOKUP($H$6,Data!$A$1:$IS$2000,5,FALSE),"")
A12: Licensed Beds* | B12: *Excluding beds in suspense | E12: =IF($B$2=1,"Type of Control","Develop. Disabled:") -> Develop. Disabled: | F12: =IF($B$2=1,VLOOKUP($H$6,Data!$A$1:$IS$1061,10,FALSE),Pivot!B181) -> 7 | G12: =IF($B$2=1,"","License Category") -> License Category
A13: Average | B13: =Pivot!B13 -> 108060 | E13: =IF($B$2=1,"Parent Organization","Sub-Acute:") -> Sub-Acute: | F13: =IF($B$2=1,IF(VLOOKUP($H$6,Data!$A$1:$IS$1061,20,FALSE)=0,"",VLOOKUP($H$6,Data!$A$1:$IS$1061,20,FALSE)),Pivot!B182) -> 82 | G13: =IF($B$2=1,"","SNF (incl. MD):") -> SNF (incl. MD): | H13: =IF($B$2=1,"",GETPIVOTDATA("Sum of SNF Lic",Pivot!$A$10)) -> 987
A14: End of Period | B14: =Pivot!B14 -> 108060 | E14: =IF($B$2=1,"Related to Others?","Sub-Acute Pediatric:") -> Sub-Acute Pediatric: | F14: =IF($B$2=1,VLOOKUP($H$6,Data!$A$1:$IS$1061,19,FALSE),Pivot!B183) -> 4 | G14: =IF($B$2=1,"","ICF (incl. DD):") -> ICF (incl. DD): | H14: =IF($B$2=1,"",GETPIVOTDATA("Sum of ICF Lic",Pivot!$A$10)) -> 6
A15: Total Patient Days | B15: =Pivot!B15 -> 34576964 | E15: =IF($B$2=1,"","Transitional Inpat.:") -> Transitional Inpat.: | F15: =IF($B$2=1,"",GETPIVOTDATA("Sum of TI Care",Pivot!$A$10)) -> 0 | G15: =IF($B$2=1,"","SNF / Residential:") -> SNF / Residential: | H15: =IF($B$2=1,"",GETPIVOTDATA("Sum of SNF/Res Lic",Pivot!$A$10)) -> 83
A16: Occupancy Rate | B16: =IF(Pivot!B16=0,"",Pivot!B15/Pivot!B16) -> 0.88519681 | E16: =IF($B$2=1,"","Hospice:") -> Hospice: | F16: =IF($B$2=1,"",GETPIVOTDATA("Sum of Hosp Care",Pivot!$A$10)) -> 0 | G16: =IF($B$2=1,"","ICF / Residential:") -> ICF / Residential: | H16: =IF($B$2=1,"",GETPIVOTDATA("Sum of ICF/Res Lic",Pivot!$A$10)) -> 0
A17: Admissions | B17: =Pivot!B17 -> 348227 | E17: =IF($B$2=1,"","Other Routine:") -> Other Routine: | F17: =IF($B$2=1,"",GETPIVOTDATA("Sum of Other Care",Pivot!$A$10)) -> 0 | G17: =IF($B$2=1,"","Other Licensure:") -> Other Licensure: | H17: =IF($B$2=1,"",GETPIVOTDATA("Sum of Other Lic",Pivot!$A$10)) -> 0
A18: Discharges | B18: =Pivot!B18 -> 346685 | E18: =IF($B$2=1,"","*Counts facilities with multiple levels twice") -> *Counts facilities with multiple levels twice
A20: Patient Days & Gross | E20: Gross Inpatient | F20: Gross Outpatient | H20: Total Net
A21: Revenue by Payer | C21: Gross Routine | D21: Per Patient | E21: Ancillary | F21: Ancillary | G21: Deductions | H21: Patient
B22: Patient Days | C22: Revenue | D22: Day | E22: Revenue | F22: Revenue | G22: from Revenue | H22: Revenue*
A23: Medicare Fee-for-Service | B23: =Pivot!B19 -> 5656431 | C23: =GETPIVOTDATA("Sum of GR_RT_MCARE_FFS2",Pivot!$A$10) -> 3432419642 | D23: =IF(B23=0,0,C23/B23) -> 606.8172 | E23: =GETPIVOTDATA("Sum of GR_AN_MCARE_FFS_IP",Pivot!$A$10) -> 2996612048 | F23: =GETPIVOTDATA("Sum of GR_AN_MCARE_FFS_OP2",Pivot!$A$10) -> 15496751 | G23: =H43 -> 710886298 | H23: =C23+E23+F23-G23 -> 5733642143
A24: % of Total | B24: =IF(B23=0,0,B23/B39) -> 0.16358958 | C24: =IF(C23=0,0,C23/C39) -> 0.2177172 | E24: =IF(E23=0,0,E23/E39) -> 0.68944012 | F24: =IF(F23=0,0,F23/F39) -> 0.92627715 | G24: =IF(G23=0,0,G23/G39) -> 0.17648977 | H24: =IF(H23=0,0,H23/H39) -> 0.35611023
A25: Medicare Managed Care | B25: =Pivot!B20 -> 2216758 | C25: =GETPIVOTDATA("Sum of GR_RT_MCARE_MGD2",Pivot!$A$10) -> 1463761135 | D25: =IF(B25=0,0,C25/B25) -> 660.31616 | E25: =GETPIVOTDATA("Sum of GR_AN_MCARE_MGD_IP2",Pivot!$A$10) -> 773650540 | F25: =GETPIVOTDATA("Sum of GR_AN_MCARE_MGD_OP2",Pivot!$A$10) -> 1196555 | G25: =H44 -> 833510112 | H25: =C25+E25+F25-G25 -> 1405098118
A26: % of Total | B26: =IF(B25=0,0,B25/B39) -> 0.064110834 | C26: =IF(C25=0,0,C25/C39) -> 0.092845868 | E26: =IF(E25=0,0,E25/E39) -> 0.17799625 | F26: =IF(F25=0,0,F25/F39) -> 0.071520898 | G26: =IF(G25=0,0,G25/G39) -> 0.20693325 | H26: =IF(H25=0,0,H25/H39) -> 0.087269105
A27: MediCal Fee-for-Service | B27: =Pivot!B21 -> 3266548 | C27: =GETPIVOTDATA("Sum of GR_RT_MCAL_FFS2",Pivot!$A$10) -> 1345700735 | D27: =IF(B27=0,0,C27/B27) -> 411.96417 | E27: =GETPIVOTDATA("Sum of GR_AN_MCAL_FFS_IP2",Pivot!$A$10) -> 90681588 | F27: =GETPIVOTDATA("Sum of GR_AN_MCAL_FFS_OP",Pivot!$A$10) -> 0 | G27: =H45 -> 186335378 | H27: =C27+E27+F27-G27 -> 1250046945
A28: % of Total | B28: =IF(B27=0,0,B27/B39) -> 0.094471799 | C28: =IF(C27=0,0,C27/C39) -> 0.085357337 | E28: =IF(E27=0,0,E27/E39) -> 0.020863403 | F28: =IF(F27=0,0,F27/F39) -> 0 | G28: =IF(G27=0,0,G27/G39) -> 0.046260968 | H28: =IF(H27=0,0,H27/H39) -> 0.077639047
A29: MediCal Managed Care | B29: =Pivot!B22 -> 19260667 | C29: =GETPIVOTDATA("Sum of GR_RT_MCAL_MGD2",Pivot!$A$10) -> 7747475616 | D29: =IF(B29=0,0,C29/B29) -> 402.24337 | E29: =GETPIVOTDATA("Sum of GR_AN_MCAL_MGD_IP",Pivot!$A$10) -> 416072176 | F29: =GETPIVOTDATA("Sum of GR_AN_MCAL_MGD_OP",Pivot!$A$10) -> 0 | G29: =H46 -> 1893851407 | H29: =C29+E29+F29-G29 -> 6269696385
A30: % of Total | B30: =IF(B29=0,0,B29/B39) -> 0.55703754 | C30: =IF(C29=0,0,C29/C39) -> 0.49141973 | E30: =IF(E29=0,0,E29/E39) -> 0.095727057 | F30: =IF(F29=0,0,F29/F39) -> 0 | G30: =IF(G29=0,0,G29/G39) -> 0.47018124 | H30: =IF(H29=0,0,H29/H39) -> 0.38940398
A31: Commercial Coverage Fee-for-Service | B31: =GETPIVOTDATA("Sum of DAYS_CC_FFS2",Pivot!$A$10) -> 370809 | C31: =GETPIVOTDATA("Sum of GR_RT_CC_FFS2",Pivot!$A$10) -> 189505695 | D31: =IF(B31=0,0,C31/B31) -> 511.06013 | E31: =GETPIVOTDATA("Sum of GR_AN_CC_FFS_IP",Pivot!$A$10) -> 165372780 | F31: =GETPIVOTDATA("Sum of GR_AN_CC_FFS_OP",Pivot!$A$10) -> 80693 | G31: =H47 -> 119821231 | H31: =C31+E31+F31-G31 -> 235137937
A32: % of Total | B32: =IF(B31=0,0,B31/B39) -> 0.010724163 | C32: =IF(C31=0,0,C31/C39) -> 0.012020281 | E32: =IF(E31=0,0,E31/E39) -> 0.038047845 | F32: =IF(F31=0,0,F31/F39) -> 0.0048232098 | G32: =IF(G31=0,0,G31/G39) -> 0.029747685 | H32: =IF(H31=0,0,H31/H39) -> 0.01460416
A33: Commercial Coverage Managed Care | B33: =GETPIVOTDATA("Sum of DAYS_CC_MGD2",Pivot!$A$10) -> 904327 | C33: =GETPIVOTDATA("Sum of GR_RT_CC_MGD2",Pivot!$A$10) -> 422184905 | D33: =IF(B33=0,0,C33/B33) -> 466.84983 | E33: =GETPIVOTDATA("Sum of GR_AN_CC_MGD_IP",Pivot!$A$10) -> 328764116 | F33: =GETPIVOTDATA("Sum of GR_AN_CC_MGD_OP2",Pivot!$A$10) -> 115064 | G33: =H48 -> 212057402 | H33: =C33+E33+F33-G33 -> 539006683
A34: % of Total | B34: =IF(B33=0,0,B33/B39) -> 0.026154031 | C34: =IF(C33=0,0,C33/C39) -> 0.026779044 | E34: =IF(E33=0,0,E33/E39) -> 0.075639812 | F34: =IF(F33=0,0,F33/F39) -> 0.0068776451 | G34: =IF(G33=0,0,G33/G39) -> 0.052646904 | H34: =IF(H33=0,0,H33/H39) -> 0.033477115
A35: Self Pay | B35: =GETPIVOTDATA("Sum of DAY_SELF",Pivot!$A$10) -> 774017 | C35: =GETPIVOTDATA("Sum of GR_RT_SELF",Pivot!$A$10) -> 328302460 | D35: =IF(B35=0,0,C35/B35) -> 424.15407 | E35: =GETPIVOTDATA("Sum of GR_AN_SELF_IP",Pivot!$A$10) -> 26125257 | F35: =GETPIVOTDATA("Sum of GR_AN_SELF_OP",Pivot!$A$10) -> 64598 | G35: =H50+H51+H52 -> 8852591 | H35: =C35+E35+F35-G35 -> 345639724
A36: % of Total | B36: =IF(B35=0,0,B35/B39) -> 0.022385337 | C36: =IF(C35=0,0,C35/C39) -> 0.020824113 | E36: =IF(E35=0,0,E35/E39) -> 0.0060107215 | F36: =IF(F35=0,0,F35/F39) -> 0.0038611739 | G36: =IF(G35=0,0,G35/G39) -> 0.0021978082 | H36: =IF(H35=0,0,H35/H39) -> 0.021467305
A37: Other Payers | B37: =GETPIVOTDATA("Sum of DAY_OTH",Pivot!$A$10) -> 2127407 | C37: =GETPIVOTDATA("Sum of GR_RT_OTH",Pivot!$A$10) -> 836145515 | D37: =IF(B37=0,0,C37/B37) -> 393.03505 | E37: =GETPIVOTDATA("Sum of GR_AN_OTH_IP",Pivot!$A$10) -> 69426448 | F37: =GETPIVOTDATA("Sum of GR_AN_OTH_OP",Pivot!$A$10) -> 36839 | G37: =H49 -> 62603397 | H37: =C37+E37+F37-G37 -> 843005405
A38: % of Total | B38: =IF(B37=0,0,B37/B39) -> 0.061526715 | C38: =IF(C37=0,0,C37/C39) -> 0.053036424 | E38: =IF(E37=0,0,E37/E39) -> 0.015973165 | F38: =IF(F37=0,0,F37/F39) -> 0.0022019534 | G38: =IF(G37=0,0,G37/G39) -> 0.015542372 | H38: =IF(H37=0,0,H37/H39) -> 0.052358142
A39: Total All Payers | B39: =B23+B25+B27+B29+B31+B33+B35+B37 -> 34576964 | C39: =SUM(C23+C25+C27+C29+C31+C33+C35+C37) -> 15765495703 | D39: =IF(B39=0,0,C39/B39) -> 455.95373 | E39: =E23+E25+E27+E29+E37 -> 4346442800 | F39: =F23+F25+F27+F29+F37 -> 16730145 | G39: =(G23+G25+G27+G29+G31+G33+G35+G37) -> 4027917816 | H39: =C39+E39+F39-G39 -> 16100750832
H40: * Gross Revenue
H41: minus Deductions
...

Sheet Patient Days Chart
A33: Profile Characteristics
A34: No. of Facilities | C34: =Profile!B$2 -> 1076
A35: Facility Name | C35: =Profile!B$3 -> (All)
A36: County | C36: =Profile!B$4 -> (All)
A37: HFPA | C37: =Profile!B$5 -> (All)
A38: Type of Care | C38: =Profile!B$6 -> (All)
A39: License Category | C39: =Profile!B$7 -> (All)
A40: Type of Control | C40: =Profile!B$8 -> (All)
A41: Licensed Bed Size | C41: =Profile!B$9 -> (All)
A42: Residential Care | C42: =Profile!B$10 -> 0

Sheet Revenue & Expense per Day Chart
A33: Profile Characteristics
A34: No. of Facilities | C34: =Profile!B$2 -> 1076
A35: Facility Name | C35: =Profile!B$3 -> (All)
A36: County | C36: =Profile!B$4 -> (All)
A37: HFPA | C37: =Profile!B$5 -> (All)
A38: Type of Care | C38: =Profile!B$6 -> (All)
A39: License Category | C39: =Profile!B$7 -> (All)
A40: Type of Control | C40: =Profile!B$8 -> (All)
A41: Licensed Bed Size | C41: =Profile!B$9 -> (All)
A42: Residential Care | C42: =Profile!B$10 -> 0

Sheet Revenue Chart
A33: Profile Characteristics
A34: No. of Facilities | C34: =Profile!B$2 -> 1076
A35: Facility Name | C35: =Profile!B$3 -> (All)
A36: County | C36: =Profile!B$4 -> (All)
A37: HFPA | C37: =Profile!B$5 -> (All)
A38: Type of Care | C38: =Profile!B$6 -> (All)
A39: License Category | C39: =Profile!B$7 -> (All)
A40: Type of Control | C40: =Profile!B$8 -> (All)
A41: Licensed Bed Size | C41: =Profile!B$9 -> (All)
A42: Residential Care | C42: =Profile!B$10 -> 0

Sheet Expense Chart
A33: Profile Characteristics
A34: No. of Facilities | C34: =Profile!B$2 -> 1076
A35: Facility Name | C35: =Profile!B$3 -> (All)
A36: County | C36: =Profile!B$4 -> (All)
A37: HFPA | C37: =Profile!B$5 -> (All)
A38: Type of Care | C38: =Profile!B$6 -> (All)
A39: License Category | C39: =Profile!B$7 -> (All)
A40: Type of Control | C40: =Profile!B$8 -> (All)
A41: Licensed Bed Size | C41: =Profile!B$9 -> (All)
A42: Residential Care | C42: =Profile!B$10 -> 0

Sheet Labor Chart
A33: Profile Characteristics
A34: No. of Facilities | C34: =Profile!B$2 -> 1076
A35: Facility Name | C35: =Profile!B$3 -> (All)
A36: County | C36: =Profile!B$4 -> (All)
A37: HFPA | C37: =Profile!B$5 -> (All)
A38: Type of Care | C38: =Profile!B$6 -> (All)
A39: License Category | C39: =Profile!B$7 -> (All)
A40: Type of Control | C40: =Profile!B$8 -> (All)
A41: Licensed Bed Size | C41: =Profile!B$9 -> (All)
A42: Residential Care | C42: =Profile!B$10 -> 0

Sheet Glossary
A1: Acid Test Ratio | B1: (See Ratios.)
A3: Activities | B3: The cost center which includes activity programs organized for the benefit of the patient, including social activities, religious programs, educational activities, and exercise activities.
A5: Administration | B5: The cost center which includes the overall management and administration of the institution, general patient accounting, communication systems, data processing, patient admissions, public relations, professional liability and non-property-related insurance, licenses and taxes, medical record activities, and procurement of supplies and equipment.
A7: Admissions | B7: The number of patients formally admitted to the facility, or transferred from a residential care unit of the facility. Does not include patients returning to the facility under a bed-hold or leave, where a bed has been held open specifically for the patient's return.
A9: Ancillary Services | B9: The group of cost centers which includes diagnostic or therapeutic services performed by specific departments of the long-term care facility (or under contract) that are not part of the general or routine patient care. Ancillary services are those special services for which charges are customarily made in addition to routine charges and include patient supplies, pharmacy, laboratory, physical therapy, and home health services.
A11: Assets | B11: Physical objects (tangible) or rights (intangible) having economic value to their owner; items or sources of wealth expressed, for accounting purposes, in terms of their cost, depreciated cost, or less frequently, some other value; hence all costs benefiting a future period.
B13: a. Current Assets - The sum of all assets that are reasonably expected to be realized in cash, sold, or consumed within one year after the balance sheet due date.
B15: b. Assets Whose Use is Limited - Assets whose use is limited either by the governing board, trust agreements, or other outside parties.
B17: c. Net Property, Plant, and Equipment - The amount invested in property, plant, and equipment less accumulated depreciation (includes construction in progress).
B19: d. Investments and Other Assets - The sum of investments in property, plant, and equipment, other investments, receivables from related parties, and noncurrent deposits and other assets.
B21: e. Intangible Assets - The sum of unamortized goodwill, loan and organizational costs, and other intangible assets.
A23: Assets to Equity Ratio | B23: (See Ratios)
A25: Balance Sheet | B25: A statement that summarizes the assets, liabilities, and equity of the facility at the end of the report period.
A27: Bed Size | B27: The average number of licensed beds for a long-term care facility.
A29: Bed Size Group | B29: Based on the number of beds licensed by the California Department of Health Services' Licensing and Certification Division. For the aggregate profiles, long-term care facilities are assigned to one of three groups: 1 through 59, 60 through 99, and 100+ beds. These groupings coincide with reimbursement rates and/or staffing requirements.
A31: Congregate Living Health Facility (CLHF) | B31: As licensed by the Department of Health Services' Licensing and Certification Division, CLHFs provide care to patients with terminal or life-threatening illness, or with catastrophic and severe injury. CLHFs provide care in a non-institutional, homelike setting.
A33: Contractual Adjustments - Managed Care | B33: The difference between gross routine and ancillary revenues for Managed Care patients (billed at the facility’s full established rates) and the amounts received or to be received.
A35: Contractual Adjustments - Medicare | B35: The difference between gross routine and ancillary revenues for Medicare patients (billed at the facility’s full established rates) and the amounts received or to be received.
A37: Contractual Adjustments – Medi-Cal | B37: The difference between gross routine and ancillary revenues for Medi-Cal patients (billed at the facility’s full established rates) and the amounts received or to be received.
A39: Contractual Adjustments - Other | B39: The difference between gross routine and ancillary revenues for Other Payer patients (billed at the facility’s full established rates) and the amounts received or to be received.
A41: Cost Center | B41: An organizational department or unit performing functional services within the hospital. Some cost centers generate patient revenue and are classified as revenue-producing cost centers, such as Skilled Nursing and Physical Therapy. Other cost centers do not generate patient revenue and are classified as non-revenue producing cost centers, such as Housekeeping and Administration.
A43: Current Ratio | B43: (See Ratios.)
A45: Debt Service Coverage Ratio | B45: (See Ratios.)
... A115: Liabilities | B115: Amounts owed by the facility (debtor) to another entity (creditor), payable in money, or in goods and services.
B117: a. Deferred Credits: Revenue received or recorded before it is earned, such as deferred income taxes or deferred third-party income.
B119: b. Net Long-term Debt: Liabilities which are not expected to be satisfied within one year of the end of the reporting period. This amount reflects the reduction for that portion of the debt which is expected to be satisfied the next year. Includes mortgage notes, capitalized lease obligations, bonds payable, and long-term related party payables.
B121: c. Current Liabilities: Short-term debt or obligations that, according to reasonable expectations, are to be satisfied within a normal operating cycle, or one year, whichever is longer. Examples include accounts payable, accrued compensation and related liabilities, short-term related party payables, and the current maturities on long-term debt.
B123: d. Total Liabilities: The sum of current liabilities, deferred income, and net long-term debt.
A125: License Category | B125: As licensed by the Department of Health Services' Licensing and Certification Division, either Skilled Nursing Facility (SNF), Intermediate Care Facility (ICF), or Congregate Living Health Facility (CLHF) (not included in this file). SNF/RES and ICF/RES indicate facilities that are licensed for skilled nursing or intermediate care, but are an integral part of a residential care facility.
A127: Licensed Beds | B127: The average number of beds licensed by the Department of Health Services, less those beds in suspense, during the reporting period.
A129: Long-term Debt to Assets Rate | B129: (See Ratios.)
A131: Managed Care | B131: Groups that have a contractual relationship with the facility such as HMO's, PPO's or others. Patients enrolled in managed care plans funded by Medicare and Medi-Cal or other government programs are included here.
A133: Medi-Cal | B133: The federally-aided, State operated and administered Medicaid program which provides medical benefits for certain low-income persons. Data related to Medi-Cal patients enrolled in health maintenance organizations (HMOs) are not included in the Medi-Cal payer category, but are part of the "Other Payer" category.
A135: Medicare | B135: A federal health insurance program designed to underwrite the medical costs of persons 65 and over, and some qualified persons under 65. Data related to Medi-Care patients enrolled in health maintenance organizations (HMOs) are not included in the Medi-Care payer category, but are part of the "Other Payer" category.
A137: Mentally Disordered (MD) | B137: A person with a chronic psychiatric impairment and whose adaptive functioning is moderately impaired. Also used to describe the nursing care given to such a person.
A139: Net Income (Loss) | B139: The amount of income from operations plus nonhealth care revenue net of nonhealth care expense, less provision for income taxes and extraordinary items. (Often called “the bottom line.”)
A141: Net Patient Services Revenue | B141: The difference between gross routine and ancillary services revenue (recorded at the facility’s full established rates) and deductions from revenue.
A143: Net PP&E Assets per Bed | B143: (See Ratios.)
A145: Nonhealth Care Revenue and Expenses | B145: Revenues and expenses not directly related to patient services. This includes residential care revenue and expense, and nonoperating gains and losses.
A147: Not-for-Profit | B147: Ownership group which includes all church-related and other facilities that are corporations organized and operated under a policy by which no stockholder or trustee shares in the profits or losses of the enterprise.
...

Sheet Chart DB
B1: MCare FFS | C1: MCare MC | D1: MCal FFS | E1: MCal MC | F1: CC FFS | G1: CC MC | H1: Self Pay | I1: Other Payers | J1: Total
A2: Patient Days | B2: =Profile!B23 -> 5656431 | C2: =Profile!B25 -> 2216758 | D2: =Profile!B27 -> 3266548 | E2: =Profile!B29 -> 19260667 | F2: =Profile!B31 -> 370809 | G2: =Profile!B33 -> 904327 | H2: =Profile!B35 -> 774017 | I2: =Profile!B37 -> 2127407 | J2: =Profile!B39 -> 34576964
B4: MCare FFS | C4: MCare MC | D4: MCal FFS | E4: MCal MC | F4: CC FFS | G4: CC MC | H4: Self Pay | I4: Other Payers | J4: Total
A5: Gross Revenue | B5: =Profile!C23+Profile!E23+Profile!F23 -> 6444528441 | C5: =Profile!C25+Profile!E25+Profile!F25 -> 2238608230 | D5: =Profile!C27+Profile!E27+Profile!F27 -> 1436382323 | E5: =Profile!C29+Profile!E29+Profile!F29 -> 8163547792 | F5: =Profile!C31+Profile!E31+Profile!F31 -> 354959168 | G5: =Profile!C33+Profile!E33+Profile!F33 -> 751064085 | H5: =Profile!C35+Profile!E35+Profile!F35 -> 354492315 | I5: =Profile!C37+Profile!E37+Profile!F37 -> 905608802 | J5: =Profile!C39+Profile!E39+Profile!F39 -> 20128668648
A6: Net Revenue | B6: =B5-Profile!H43 -> 5733642143 | C6: =C5-Profile!H44 -> 1405098118 | D6: =D5-Profile!H45 -> 1250046945 | E6: =E5-Profile!H46 -> 6269696385 | F6: =F5-Profile!H47 -> 235137937 | G6: =G5-Profile!H48 -> 539006683 | H6: =H5-Profile!H50-Profile!H51-Profile!H52 -> 345639724 | I6: =I5-Profile!H49 -> 843005405 | J6: =J5-Profile!H53 -> 16100750832
B9: MCare FFS | C9: MCare MC | D9: MCal FFS | E9: MCal MC | F9: CC FFS | G9: CC MC | H9: Self Pay | I9: Other Payers | J9: Total
A10: Gross Routine Revenue per Patient Day | B10: =Profile!D23 -> 606.8172 | C10: =Profile!D25 -> 660.31616 | D10: =Profile!D27 -> 411.96417 | E10: =Profile!D29 -> 402.24337 | F10: =Profile!D31 -> 511.06013 | G10: =Profile!D33 -> 466.84983 | H10: =Profile!D35 -> 424.15407 | I10: =Profile!D37 -> 393.03505 | J10: =Profile!D39 -> 455.95373
B12: Routine Care | C12: Ancillary Care | D12: Support Services | E12: Administration | F12: Property | G12: Other | H12: Total
A13: Expenses | B13: =Profile!B67 -> 6636105010 | C13: =Profile!B79 -> 1508759905 | D13: =Profile!B89-Profile!B88 -> 2713199909 | E13: =Profile!B88 -> 3589927857 | F13: =Profile!B96 -> 1301429622 | G13: =Profile!B100 -> 277401124 | H13: =Profile!B101 -> 16026823427
B15: Routine Nursing | C15: Ancillary | D15: Support Services | E15: Administration | F15: Temporary Nursing | G15: Total
A16: Hours per Patient Day | B16: =Profile!G116 -> 4.123917 | C16: =Profile!G124 -> 0.27219715 | D16: =Profile!G134-Profile!G133 -> 1.6029171 | E16: =Profile!G133 -> 0.52127038 | F16: =Profile!G141 -> 0.18968062 | G16: =Profile!G136+Profile!G141 -> 6.7099823
B18: Routine Care Expense | C18: Ancillary Care Expense | D18: Support Services Expense | E18: Admin. Expense | F18: Property Expense | G18: Other Expenses | H18: Total Expense | I18: Net Patient Revenue
A19: Per Patient Day | B19: =B13/$J2 -> 191.92272 | C19: =C13/J2 -> 43.634829 | D19: =D13/$J2 -> 78.468425 | E19: =E13/$J2 -> 103.82426 | F19: =F13/$J2 -> 37.638632 | G19: =G13/$J2 -> 8.0227149 | H19: =H13/$J2 -> 463.51159 | I19: =J6/J2 -> 465.64964

Sheet Data
A1: FAC_NO | B1: FAC_NAME | C1: BEG_DATE | D1: END_DATE | E1: DAY_PER | F1: DATA_IND | G1: ResCare | H1: County | I1: License Category | J1: TYPE_CNTRL | K1: HSA | L1: HFPA | M1: PHONE | N1: ADDRESS | O1: CITY | P1: ZIP_CODE | Q1: MCAL_PRO# | R1: ADMINIS | S1: RELATED | T1: PARENT | U1: BED_END | V1: BED_AVG | W1: Bed Size | X1: Licensed Bed Days | Y1: DAY_TOTL | Z1: OCCUP | AA1: ADMITS | AB1: DISCHS | AC1: DAYS_MCARE_FFS | AD1: DAYS_MCARE_MGD | AE1: DAYS_MCAL_FFS | AF1: DAYS_MCAL_MGD | AG1: DAYS_CC_FFS | AH1: DAYS_CC_MGD | AI1: DAY_SELF | AJ1: DAY_OTH | AK1: Type of Care | AL1: DAY_SN | AM1: DAY_IC | AN1: DAY_MD | AO1: DAY_DD | AP1: DAY_SUBACU | AQ1: DAY_SUBPED | AR1: DAY_TIC | AS1: DAY_HOSPIC | AT1: DAY_OTH_RT | AU1: GR_RT_TOTL | AV1: GR_AN_TOTL | AW1: DFR_TOTL | AX1: OTH_OP_REV | AY1: TOT_HC_REV | AZ1: TOT_HC_EXP | BA1: NET_FRM_HC | BB1: NONHC_NET | BC1: INC_TAX | BD1: EXT_ITEM | BE1: NET_INCOME | BF1: GR_RT_MCARE_FFS | BG1: GR_RT_MCARE_MGD | BH1: GR_RT_MCAL_FFS | BI1: GR_RT_MCAL_MGD | BJ1: GR_RT_CC_FFS | BK1: GR_RT_CC_MGD | BL1: GR_RT_SELF | BM1: GR_RT_OTH | BN1: GR_SN | BO1: GR_IC | BP1: GR_MD | BQ1: GR_DD | BR1: GR_SUBACU | BS1: GR_SUBPED | BT1: GR_TIC | BU1: GR_HOSPIC | BV1: GR_OTH_RT | BW1: GR_AN_MCARE_FFS_IP | BX1: GR_AN_MCARE_FFS_OP | BY1: GR_AN_MCARE_MGD_IP | BZ1: GR_AN_MCARE_MGD_OP | CA1: GR_AN_MCAL_FFS_IP | CB1: GR_AN_MCAL_FFS_OP | CC1: GR_AN_MCAL_MGD_IP | CD1: GR_AN_MCAL_MGD_OP | CE1: GR_AN_CC_FFS_IP | CF1: GR_AN_CC_FFS_OP | CG1: GR_AN_CC_MGD_IP | CH1: GR_AN_CC_MGD_OP | CI1: GR_AN_SELF_IP | CJ1: GR_AN_SELF_OP | CK1: GR_AN_OTH_IP | CL1: GR_AN_OTH_OP | CM1: GR_PSUPPLY | CN1: GR_SPSURF | CO1: GR_PT | CP1: GR_RT | CQ1: GR_OT | CR1: GR_SP | CS1: GR_PHARM | CT1: GR_LAB | CU1: GR_HMHLTH | CV1: GR_OTH_AN | CW1: DFR_IP_MCARE_FFS_CHARITY | CX1: DFR_OP_MCARE_FFS_CHARITY | CY1: DFR_IP_MCARE_MGD_CHARITY | CZ1: DFR_OP_MCARE_MGD_CHARITY | DA1: DFR_IP_MCAL_FFS_CHARITY | DB1: DFR_OP_MCAL_FFS_CHARITY | DC1: DFR_IP_MCAL_MGD_CHARITY | DD1: DFR_OP_MCAL_MGD_CHARITY | DE1: DFR_IP_CC_FFS_CHARITY | DF1: DFR_OP_CC_FFS_CHARITY | DG1: DFR_IP_CC_MGD_CHARITY | DH1: DFR_OP_CC_MGD_CHARITY | DI1: DFR_IP_SELF_PAY_CHARITY | DJ1: DFR_OP_SELF_PAY_CHARITY | DK1: DFR_IP_OTHER_PAYERS_CHARITY | DL1: DFR_OP_OTHER_PAYERS_CHARITY | DM1: DFR_IP_MCARE_FFS_ADM_ADJ | DN1: DFR_OP_MCARE_FFS_ADM_ADJ | DO1: DFR_IP_MCARE_MGD_ADM_ADJ | DP1: DFR_OP_MCARE_MGD_ADM_ADJ | DQ1: DFR_IP_MCAL_FFS_ADM_ADJ | DR1: DFR_OP_MCAL_FFS_ADM_ADJ | DS1: DFR_IP_MCAL_MGD_ADM_ADJ | DT1: DFR_OP_MCAL_MGD_ADM_ADJ | DU1: DFR_IP_CC_FFS_ADM_ADJ | DV1: DFR_OP_CC_FFS_ADM_ADJ | DW1: DFR_IP_CC_MGD_ADM_ADJ | DX1: DFR_OP_CC_MGD_ADM_ADJ | DY1: DFR_IP_SELF_PAY_ADM_ADJ | DZ1: DFR_OP_SELF_PAY_ADM_ADJ | EA1: DFR_IP_OTHER_PAYERS_ADM_ADJ | EB1: DFR_OP_OTHER_PAYERS_ADM_ADJ | EC1: DFR_IP_MCARE_FFS_CONT_ADJ | ED1: DFR_OP_MCARE_FFS_CONT_ADJ | EE1: DFR_IP_MCARE_MGD_CONT_ADJ | EF1: DFR_OP_MCARE_MGD_CONT_ADJ | EG1: DFR_IP_MCAL_FFS_CONT_ADJ | EH1: DFR_OP_MCAL_FFS_CONT_ADJ | EI1: DFR_IP_MCAL_MGD_CONT_ADJ | EJ1: DFR_OP_MCAL_MGD_CONT_ADJ | EK1: DFR_IP_CC_FFS_CONT_ADJ | EL1: DFR_OP_CC_FFS_CONT_ADJ | EM1: DFR_IP_CC_MGD_CONT_ADJ | EN1: DFR_OP_CC_MGD_CONT_ADJ | EO1: DFR_IP_OTHER_PAYERS_CONT_ADJ | EP1: DFR_OP_OTHER_PAYERS_CONT_ADJ | EQ1: DFR_IP_MCARE_FFS_OTH_DFR | ER1: DFR_OP_MCARE_FFS_OTH_DFR | ES1: DFR_IP_MCARE_MGD_OTH_DFR | ET1: DFR_OP_MCARE_MGD_OTH_DFR | EU1: DFR_IP_MCAL_FFS_OTH_DFR | EV1: DFR_OP_MCAL_FFS_OTH_DFR | EW1: DFR_IP_MCAL_MGD_OTH_DFR | EX1: DFR_OP_MCAL_MGD_OTH_DFR | EY1: DFR_IP_CC_FFS_OTH_DFR | EZ1: DFR_OP_CC_FFS_OTH_DFR | FA1: DFR_IP_CC_MGD_OTH_DFR | FB1: DFR_OP_CC_MGD_OTH_DFR | FC1: DFR_IP_SELF_PAY_OTH_DFR | FD1: DFR_OP_SELF_PAY_OTH_DFR | FE1: DFR_IP_OTHER_PAYERS_OTH_DFR | FF1: DFR_OP_OTHER_PAYERS_OTH_DFR | FG1: EXP_SAL | FH1: EXP_BEN | FI1: EXP_OTHER | FJ1: WORK_COMP | FK1: EXP_SN | FL1: EXP_IC | FM1: EXP_MD | FN1: EXP_DD | FO1: EXP_SUBACU | FP1: EXP_SUBPED | FQ1: EXP_TIC | FR1: EXP_HOSPIC | FS1: EXP_OTH_RT | FT1: EXP_PSUPPL | FU1: EXP_SPSURF | FV1: EXP_PT | FW1: EXP_RT | FX1: EXP_OT | FY1: EXP_SP | FZ1: EXP_PHARM | GA1: EXP_LAB | GB1: EXP_HMHLTH | GC1: EXP_OTH_AN | GD1: EXP_POM | GE1: EXP_HKP | GF1: EXP_LL | GG1: EXP_DIET | GH1: EXP_SS | GI1: EXP_ACTV | GJ1: EXP_INSV | GK1: EXP_ADMN | GL1: EXP_DPREC | GM1: EXP_LEASE | GN1: EXP_PRPTAX | GO1: EXP_PRPINS | GP1: EXP_INTPPE | GQ1: EXP_INTOTH | GR1: EXP_BDEBT | GS1: CUR_ASST | GT1: ASST_LIMTD | GU1: NET_PPE | GV1: CONST_PROG | GW1: INV_OTH | GX1: INTAN_ASST | GY1: TOT_ASST | GZ1: CUR_LIAB | HA1: DEF_CRED | HB1: NET_LTDEBT | HC1: EQUITY | HD1: LIAB_EQ | HE1: REL_REC_CR | HF1: REL_REC_LT | HG1: REL_PAY_CR | HH1: REL_PAY_LT | HI1: LAND&IMP | HJ1: BLDGS&IMP | HK1: LEASE_IMP | HL1: EQUIPMENT | HM1: TOT_PPE | HN1: ACC_DEPREC | HO1: MORT_PAY | HP1: CAP_LEASE | HQ1: BOND_PAY | HR1: TOT_LTDEBT | HS1: CUR_MAT | HT1: ACID_RATIO | HU1: Cash & Securities | HV1: PRDHR_MGT | HW1: PRDHR_GNP | HX1: PRDHR_RN | HY1: PRDHR_LVN | HZ1: PRDHR_NA | IA1: PRDHR_TSP | IB1: PRDHR_PSY | IC1: PRDHR_OTH | ID1: PRDHR_AN | IE1: PRDHR_POM | IF1: PRDHR_HKP | IG1: PRDHR_LL | IH1: PRDHR_DIET | II1: PRDHR_SS | IJ1: PRDHR_ACTV | IK1: PRDHR_INSV | IL1: PRDHR_ADMN | IM1: PRDHR_TOTL | IN1: TMP_HR_GNP | IO1: TMP_HR_RN | IP1: TMP_HR_LVN | IQ1: TMP_HR_NA | IR1: TMP_HR_PSY | IS1: TMP_HR_OTH | IT1: TMP_HR_TOT | IU1: S&W_MGT | IV1: S&W_GNP | IW1: S&W_RN | IX1: S&W_LVN | IY1: S&W_NA | IZ1: S&W_TSP | JA1: S&W_PSY | JB1: S&W_OTH | JC1: S&W_ANC | JD1: S&W_POM | JE1: S&W_HKP | JF1: S&W_LL | JG1: S&W_DIET | JH1: S&W_SS | JI1: S&W_ACTV | JJ1: S&W_INSV | JK1: S&W_ADMN | JL1: S&W_TOTL | JM1: TMP_PD_GNP | JN1: TMP_PD_RN | JO1: TMP_PD_LVN | JP1: TMP_PD_NA | JQ1: TMP_PD_PSY | JR1: TMP_PD_OTH | JS1: TMP_PD_TOT | JT1: HRS_SUP&MGMT_ANCILLARY | JU1: HRS_RN_ANCILLARY | JV1: HRS_LVN_ANCILLARY | JW1: HRS_NA_ANCILLARY | JX1: HRS_TECH/SPEC_ANCILLARY | JY1: HRS_OTHER_ANCILLARY | JZ1: S&W_SUP&MGMT_ANCILLARY | KA1: S&W_RN_ANCILLARY | KB1: S&W_LVN_ANCILLARY | KC1: S&W_NA_ANCILLARY | KD1: S&W_TECH/SPEC_ANCILLARY | KE1: S&W_OTHER_ANCILLARY | KF1: EMP_TOTAL_AVG | KG1: EMP_TOTAL_TOTAL | KH1: EMP_TOTAL_CONT | KI1: EMP_NRSG_AVG | KJ1: EMP_NRSG_TOTAL | KK1: EMP_NRSG_CONT | KL1: EMP_NA_AVG | KM1: EMP_NA_TOTAL | KN1: EMP_NA_CONT | KO1: Investor | KP1: Not-for-profit | KQ1: Governmental | KR1: 1-59 Beds | KS1: 60-99 Beds | KT1: 100+ Beds | KU1: SN Care | KV1: IC Care | KW1: MD Care | KX1: DD Care | KY1: SA Care | KZ1: SAP Care | LA1: TI Care | LB1: Hosp Care | LC1: Other Care | LD1: SNF Lic | LE1: ICF Lic | LF1: SNF/Res Lic | LG1: ICF/Res Lic | LH1: Other Lic
A2: 206010734 | B2: CROWN BAY NURSING AND REHABILITATION CENTER | C2: 45292 | D2: 45657 | E2: 366 | F2: In Process | G2: No | H2: Alameda | I2: SNF | J2: Investor Owned | K2: 05 - East Bay | L2: 0417 | M2: 510-521-5765 | N2: 508 WESTLINE DRIVE | O2: ALAMEDA | P2: 94501 | Q2: ZZR06103H | R2: RUBY SINGH | S2: Yes | U2: 151 | V2: 151 | W2: 100+ | X2: 55266 | Y2: 43622 | Z2: 186.38 | AA2: 516 | AB2: 409 | AC2: 2219 | AE2: 13071 | AF2: 19847 | AH2: 6287 | AI2: 950 | AJ2: 1248 | AK2: Skilled Nursing Care Only | AL2: 43622 | AU2: 16180094 | AV2: 3077943 | AW2: -442223 | AX2: 4892 | AY2: 19705152 | AZ2: 20843140 | BA2: -1137988 | BB2: 225160 | BE2: -912828 | BF2: 750500 | BH2: 5032335 | BI2: 7641095 | BK2: 2053700 | BL2: 304844 | BM2: 397620 | BN2: 16180094 | BW2: 930586 | CA2: 12686 | CC2: 19266 | CG2: 2108636 | CI2: 6769 | CM2: 4189 | CN2: 0 | CO2: 1014780 | CP2: 0 | CQ2: 887722 | CR2: 68437 | CS2: 956381 | CT2: 107388 | CV2: 39046 | DM2: -21087 | EC2: -783300 | EG2: -1692785 | EI2: 2160066 | EM2: -84632 | EO2: -20485 | FG2: 9513509 | FH2: 2527692 | FI2: 8801939 | FK2: 9380484 | FT2: 909 | FU2: 11363 | FV2: 546539 | FX2: 394128 | FY2: 44160 | FZ2: 292592 | GA2: 61802 | GC2: 28815 | GD2: 680161 | GE2: 779061 | GF2: 247793 | GG2: 1567644 | GH2: 189105 | GI2: 345997 | GJ2: 252899 | GK2: 3964205 | GL2: 18960 | GM2: 1132834 | GN2: 139280 | GO2: 31727 | GQ2: 337036 | GR2: 395646 | GS2: 5112726 | GT2: 30596 | GU2: 80550 | GV2: 66883 | GW2: 4223208 | GY2: 9513963 | GZ2: 4040784 | HC2: 5473179 | HD2: 9513963 | HF2: 4223208 | HI2: 0 | HK2: 92241 | HL2: 387575 | HM2: 479816 | HN2: -399266 | HT2: -0.01 | HU2: -40407.84 | HV2: 1771 | HW2: 0 | HX2: 9783 | HY2: 48888 | HZ2: 94509 | IA2: 0 | IB2: 0 | IC2: 5979 | IE2: 3683 | IF2: 25630 | IG2: 6091 | IH2: 29229 | II2: 3889 | IJ2: 11816 | IK2: 4226 | IL2: 16919 | IM2: 262413 | IN2: 0 | IO2: 1236 | IP2: 0 | IQ2: 22511 | IR2: 0 | IS2: 19697 | IT2: 43444 | IU2: 136779 | IV2: 0 | IW2: 762963 | IX2: 2414139 | IY2: 2972129 | IZ2: 0 | JA2: 0 | JB2: 355287 | JD2: 105847 | JE2: 565624 | JF2: 120567 | JG2: 717972 | JH2: 150485 | JI2: 272209 | JJ2: 194869 | JK2: 744639 | JL2: 9513509 | JM2: 0 | JN2: 49459 | JO2: 0 | JP2: 450215 | JQ2: 0 | JR2: 984827 | JS2: 1484501 | KF2: 156 | KG2: 234 | KH2: 104 | KI2: 98 | KJ2: 157 | KK2: 60 | KL2: 57 | KM2: 91 | KN2: 29 | KO2: 1 | KP2: 0 | KQ2: 0 | KR2: 0 | KS2: 0 | KT2: 1 | KU2: 1 | KV2: 0 | KW2: 0 | KX2: 0 | KY2: 0 | KZ2: 0 | LA2: 0 | LB2: 0 | LC2: 0 | LD2: 1 | LE2: 0 | LF2: 0 | LG2: 0 | LH2: 0
A3: 206010744 | B3: ASHBY CARE CENTER | C3: 45292 | D3: 45657 | E3: 366 | F3: In Process | G3: No | H3: Alameda | I3: SNF | J3: Investor Owned | K3: 05 - East Bay | L3: 0415 | M3: 510-841-9494 | N3: 2270 ASHBY AVENUE | O3: BERKELEY | P3: 94705 | Q3: LTM90004I | R3: RUBY SANTIAGO | S3: No | U3: 31 | V3: 31 | W3: 1-59 | X3: 11346 | Y3: 10576 | Z3: 218.69 | AA3: 16 | AB3: 17 | AC3: 301 | AE3: 9541 | AG3: 2 | AI3: 732 | AK3: Skilled Nursing Care Only | AL3: 10576 | AU3: 2409403 | AV3: 64939 | AW3: -147199 | AY3: 2621541 | AZ3: 2585336 | BA3: 36205 | BC3: 848 | BE3: 35357 | BF3: 107280 | BH3: 2073971 | BJ3: 440 | BL3: 227712 | BN3: 2409403 | BW3: 58171 | CA3: 1922 | CE3: 1475 | CI3: 3371 | CM3: 1813 | CN3: 0 | CO3: 45116 | CP3: 0 | CQ3: 0 | CR3: 0 | CS3: 15885 | CT3: 2125 | CV3: 0 | EC3: -167856 | EG3: 21900 | EK3: -1243 | FG3: 1198696 | FH3: 161375 | FI3: 1225265 | FJ3: 65951 | FK3: 1208858 | FV3: 11956 | FX3: 24667 | FY3: 2940 | FZ3: 15677 | GA3: 3274 | GC3: 1792 | GD3: 162230 | GE3: 60261 | GF3: 27086 | GG3: 233049 | GH3: 612 | GI3: 661 | GJ3: 10856 | GK3: 463757 | GL3: 637 | GM3: 227207 | GN3: 544 | GO3: 9417 | GQ3: 1379 | GR3: 118476 | GS3: 897299 | GU3: 4130 | GX3: 175000 | GY3: 1076429 | GZ3: 1500473 | HC3: -424044 | HD3: 1076429 | HG3: 658189 | HI3: 0 | HL3: 63178 | HM3: 63178 | HN3: -59048 | HT3: 0.07 | HU3: 105033.11 | HV3: 2080 | HW3: 0 | HX3: 4404 | HY3: 3925 | HZ3: 16682 | IA3: 0 | IB3: 0 | IC3: 200 | IE3: 2494 | IF3: 1348 | IG3: 1044 | IH3: 4906 | II3: 20 | IJ3: 20 | IK3: 144 | IL3: 2580 | IM3: 39847 | IN3: 0 | IO3: 0 | IP3: 0 | IQ3: 2763 | IR3: 0 | IS3: 0 | IT3: 2763 | IU3: 96000 | IV3: 0 | IW3: 207115 | IX3: 161182 | IY3: 457782 | IZ3: 0 | JA3: 0 | JB3: 8000 | JD3: 50214 | JE3: 26354 | JF3: 18332 | JG3: 116633 | JH3: 580 | JI3: 580 | JJ3: 9554 | JK3: 46370 | JL3: 1198696 | JM3: 0 | JN3: 0 | JO3: 0 | JP3: 120221 | JQ3: 0 | JR3: 0 | JS3: 120221 | KF3: 22 | KG3: 30 | KH3: 19 | KI3: 16 | KJ3: 23 | KK3: 15 | KL3: 11 | KM3: 16 | KN3: 10 | KO3: 1 | KP3: 0 | KQ3: 0 | KR3: 1 | KS3: 0 | KT3: 0 | KU3: 1 | KV3: 0 | KW3: 0 | KX3: 0 | KY3: 0 | KZ3: 0 | LA3: 0 | LB3: 0 | LC3: 0 | LD3: 1 | LE3: 0 | LF3: 0 | LG3: 0 | LH3: 0
A4: 206010747 | B4: BANCROFT HEALTHCARE CENTER | C4: 45292 | D4: 45657 | E4: 366 | F4: In Process | G4: No | H4: Alameda | I4: SNF | J4: Investor Owned | K4: 05 - East Bay | L4: 0421 | M4: 510-483-1680 | N4: 1475 BANCROFT AVENUE | O4: SAN LEANDRO | P4: 94577-5105 | Q4: ZZR05107F | R4: JEFFREY TONG | S4: Yes | U4: 36 | V4: 36 | W4: 1-59 | X4: 13176 | Y4: 12251 | Z4: 218.14 | AA4: 100 | AB4: 53 | AC4: 592 | AE4: 819 | AF4: 10501 | AI4: 339 | AK4: Skilled Nursing Care Only | AL4: 12251 | AU4: 5208005 | AV4: 455982 | AW4: 1736094 | AX4: 43071 | AY4: 3970964 | AZ4: 4920136 | BA4: -949172 | BB4: 639118 | BE4: -310054 | BF4: 224825 | BH4: 424150 | BI4: 4414050 | BL4: 144980 | BN4: 5208005 | BW4: 320313 | CA4: 24220 | CC4: 77207 | CI4: 34242 | CM4: 87432 | CN4: 0 | CO4: 208780 | CP4: 0 | CQ4: 33287 | CR4: 25199 | CS4: 90331 | CT4: 7917 | CV4: 3036 | EC4: -101761 | EG4: 213476 | EI4: 1624379 | FG4: 2364132 | FH4: 417402 | FI4: 2138602 | FJ4: 31490 | FK4: 2100483 | FT4: 2776 | FV4: 70735 | FX4: 13085 | FY4: 10793 | FZ4: 24423 | GA4: 2887 | GC4: 1664 | GD4: 190685 | GE4: 130087 | GF4: 34949 | GG4: 360249 | GH4: 60842 | GI4: 48474 | GK4: 922565 | GL4: 32156 | GM4: 854561 | GN4: 32043 | GO4: 13020 | GP4: 751 | GR4: 12908 | GS4: 998313 | GT4: 1343698 | GU4: 59651 | GX4: 80000 | GY4: 2481662 | GZ4: 777488 | HC4: 1704174 | HD4: 2481662 | HG4: 395000 | HI4: 0 | HL4: 308704 | HM4: 308704 | HN4: -249053 | HT4: 1.30 | HU4: 1010734.4 | HV4: 2449 | HW4: 0 | HX4: 1400 | HY4: 12218 | HZ4: 25847 | IA4: 0 | IB4: 0 | IC4: 1434 | IE4: 2003 | IF4: 4022 | IG4: 1529 | IH4: 8842 | II4: 1726 | IJ4: 1883 | IL4: 6541 | IM4: 69894 | IN4: 0 | IO4: 8 | IP4: 23 | IQ4: 2483 | IR4: 0 | IS4: 0 | IT4: 2514 | IU4: 134719 | IV4: 0 | IW4: 67615 | IX4: 507371 | IY4: 772131 | IZ4: 0 | JA4: 0 | JB4: 137865 | JD4: 37578 | JE4: 87436 | JF4: 24842 | JG4: 199614 | JH4: 51285 | JI4: 39632 | JK4: 304044 | JL4: 2364132 | JM4: 0 | JN4: 552 | JO4: 2201 | JP4: 89707 | JQ4: 0 | JR4: 0 | JS4: 92460 | KF4: 41 | KG4: 65 | KH4: 31 | KI4: 23 | KJ4: 37 | KK4: 14 | KL4: 12 | KM4: 23 | KN4: 5 | KO4: 1 | KP4: 0 | KQ4: 0 | KR4: 1 | KS4: 0 | KT4: 0 | KU4: 1 | KV4: 0 | KW4: 0 | KX4: 0 | KY4: 0 | KZ4: 0 | LA4: 0 | LB4: 0 | LC4: 0 | LD4: 1 | LE4: 0 | LF4: 0 | LG4: 0 | LH4: 0
A5: 206010749 | B5: ST. FRANCIS HEALTHCARE CENTER | C5: 45292 | D5: 45657 | E5: 366 | F5: In Process | G5: No | H5: Alameda | I5: SNF | J5: Investor Owned | K5: 05 - East Bay | L5: 0421 | M5: 510-785-3630 | N5: 718 BARTLETT AVE | O5: HAYWARD | P5: 94541-0000 | Q5: 1164984381 | R5: STEVEN STOCK | S5: Yes | U5: 62 | V5: 62 | W5: 60-99 | X5: 22692 | Y5: 18376 | Z5: 189.99 | AA5: 252 | AB5: 270 | AC5: 6230 | AD5: 3049 | AE5: 1013 | AF5: 6326 | AI5: 22 | AJ5: 1736 | AK5: Skilled Nursing Care Only | AL5: 18376 | AU5: 16683100 | AV5: 4307758 | AW5: 8453965 | AX5: 9015 | AY5: 12545908 | AZ5: 11939020 | BA5: 606888 | BB5: -2 | BE5: 606886 | BF5: 7787500 | BG5: 3763650 | BH5: 557150 | BI5: 3607900 | BL5: 12100 | BM5: 954800 | BN5: 16683100 | BW5: 3170668 | BY5: 1132951 | CA5: 325 | CC5: 225 | CI5: 3589 | CM5: 8412 | CN5: 30114 | CO5: 1446300 | CP5: 3310 | CQ5: 1463550 | CR5: 372900 | CS5: 621636 | CT5: 291972 | CV5: 69564 | EC5: 3417964 | EE5: 2850651 | EG5: 206278 | EI5: 1543301 | EO5: 435771 | FG5: 5150068 | FH5: 1333734 | FI5: 5455218 | FJ5: 128614 | FK5: 4460677 | FT5: 3091 | FU5: 20076 | FV5: 619001 | FW5: 2988 | FX5: 461309 | FY5: 130134 | FZ5: 270525 | GA5: 123812 | GC5: 85297 | GD5: 354494 | GE5: 430339 | GF5: 94686 | GG5: 681026 | GH5: 81556 | GI5: 153411 | GJ5: 119887 | GK5: 2505590 | GL5: 44188 | GM5: 581852 | GN5: 51535 | GO5: 57272 | GQ5: 8450 | GR5: 597824 | GS5: 9580861 | GU5: 866918 | GV5: 8796 | GY5: 10456575 | GZ5: 1470531 | HC5: 8986044 | HD5: 10456575 | HE5: 7879801 | HI5: 0 | HK5: 802239 | HL5: 219109 | HM5: 1021348 | HN5: -154430 | HT5: 0.00 | HU5: 0 | HV5: 2040 | HW5: 0 | HX5: 11846 | HY5: 18321 | HZ5: 44421 | IA5: 0 | IB5: 0 | IC5: 0 | ID5: 10235 | IE5: 2038 | IF5: 11515 | IG5: 5347 | IH5: 15202 | II5: 1683 | IJ5: 4656 | IK5: 2113 | IL5: 12412 | IM5: 141829 | IN5: 0 | IO5: 606 | IP5: 902 | IQ5: 9161 | IR5: 0 | IS5: 0 | IT5: 10669 | IU5: 219849 | IV5: 0 | IW5: 630271 | IX5: 782456 | IY5: 1209088 | IZ5: 0 | JA5: 0 | JB5: 0 | JC5: 656053 | JD5: 56680 | JE5: 268089 | JF5: 63404 | JG5: 362048 | JH5: 53038 | JI5: 104931 | JJ5: 96551 | JK5: 647610 | JL5: 5150068 | JM5: 0 | JN5: 49295 | JO5: 60030 | JP5: 384470 | JQ5: 0 | JR5: 0 | JS5: 493795 | JY5: 10235 | KE5: 656053 | KF5: 85 | KG5: 167 | KH5: 42 | KI5: 53 | KJ5: 114 | KK5: 20 | KL5: 27 | KM5: 59 | KN5: 11 | KO5: 1 | KP5: 0 | KQ5: 0 | KR5: 0 | KS5: 1 | KT5: 0 | KU5: 1 | KV5: 0 | KW5: 0 | KX5: 0 | KY5: 0 | KZ5: 0 | LA5: 0 | LB5: 0 | LC5: 0 | LD5: 1 | LE5: 0 | LF5: 0 | LG5: 0 | LH5: 0
A6: 206010750 | B6: VISTA POST ACUTE | C6: 45292 | D6: 45657 | E6: 366 | F6: In Process | G6: No | H6: Alameda | I6: SNF | J6: Investor Owned | K6: 05 - East Bay | L6: 0421 | M6: 510-537-6700 | N6: 3269 D STREET | O6: HAYWARD | P6: 94541 | Q6: 1790261014 | R6: SARAH R WILCOX | S6: Yes | U6: 71 | V6: 71 | W6: 60-99 | X6: 25986 | Y6: 24750 | Z6: 219.24 | AA6: 150 | AB6: 132 | AC6: 2974 | AE6: 1055 | AF6: 15274 | AH6: 2562 | AJ6: 2885 | AK6: Skilled Nursing Care Only | AL6: 24750 | AU6: 9532768 | AV6: 2328491 | AW6: 102827 | AX6: 50513 | AY6: 11808945 | AZ6: 10316222 | BA6: 1492723 | BB6: 19671 | BE6: 1512394 | BF6: 1145473 | BH6: 406346 | BI6: 5882970 | BK6: 986786 | BM6: 1111193 | BN6: 9532768 | BW6: 1697566 | CA6: 36403 | CC6: 527025 | CG6: 67497 | CM6: 2723 | CN6: 21698 | CO6: 413509 | CP6: 599188 | CQ6: 667620 | CR6: 323185 | CS6: 147118 | CT6: 79106 | CV6: 74344 | EC6: -686718 | EG6: 753262 | EI6: -1968452 | EM6: 893542 | EO6: 1111193 | FG6: 5201664 | FH6: 947217 | FI6: 4167341 | FJ6: 197252 | FK6: 4492989 | FV6: 236383 | FX6: 231210 | FY6: 64308 | FZ6: 81697 | GA6: 39588 | GC6: 18108 | GD6: 527485 | GE6: 129938 | GF6: 117533 | GG6: 701777 | GH6: 52137 | GI6: 43325 | GK6: 2527131 | GL6: 6116 | GM6: 604135 | GN6: 85083 | GO6: 91000 | GR6: 266279 | GS6: 7988421 | GU6: 201092 | GY6: 8189513 | GZ6: 4179632 | HC6: 4009881 | HD6: 8189513 | HE6: 5344060 | HG6: 2220610 | HI6: 0 | HK6: 198670 | HL6: 51842 | HM6: 250512 | HN6: -49420 | HT6: 0.18 | HU6: 752333.76 | HV6: 1588 | HW6: 0 | HX6: 7517 | HY6: 24191 | HZ6: 65710 | IA6: 0 | IB6: 0 | IC6: 2093 | ID6: 6341 | IE6: 9634 | IF6: 6159 | IG6: 4297 | IH6: 15867 | II6: 1231 | IJ6: 563 | IL6: 12154 | IM6: 157345 | IN6: 0 | IO6: 0 | IP6: 0 | IQ6: 0 | IR6: 0 | IS6: 0 | IT6: 0 | IU6: 136994 | IV6: 0 | IW6: 417527 | IX6: 1047972 | IY6: 1689431 | IZ6: 0 | JA6: 0 | JB6: 105190 | JC6: 342328 | JD6: 197637 | JE6: 108710 | JF6: 77375 | JG6: 314662 | JH6: 43190 | JI6: 10137 | JK6: 710511 | JL6: 5201664 | JM6: 0 | JN6: 0 | JO6: 0 | JP6: 0 | JQ6: 0 | JR6: 0 | JS6: 0 | JY6: 6341 | KE6: 342328 | KF6: 94 | KG6: 145 | KH6: 54 | KI6: 65 | KJ6: 101 | KK6: 35 | KL6: 43 | KM6: 65 | KN6: 23 | KO6: 1 | KP6: 0 | KQ6: 0 | KR6: 0 | KS6: 1 | KT6: 0 | KU6: 1 | KV6: 0 | KW6: 0 | KX6: 0 | KY6: 0 | KZ6: 0 | LA6: 0 | LB6: 0 | LC6: 0 | LD6: 1 | LE6: 0 | LF6: 0 | LG6: 0 | LH6: 0
A7: 206010757 | B7: BERKELEY PINES SKILLED NURSING CENTER | C7: 45292 | D7: 45657 | E7: 366 | F7: In Process | G7: No | H7: Alameda | I7: SNF | J7: Investor Owned | K7: 05 - East Bay | L7: 0415 | M7: 510-649-6670 | N7: 2223 ASHBY AVENUE | O7: BERKELEY | P7: 94705-0000 | Q7: ZZR05892J | R7: ALFREDO MACASIEB | S7: Yes | U7: 36 | V7: 36 | W7: 1-59 | X7: 13176 | Y7: 12809 | Z7: 228.08 | AA7: 36 | AB7: 24 | AC7: 518 | AE7: 879 | AF7: 11111 | AI7: 301 | AK7: Skilled Nursing Care Only | AL7: 12809 | AU7: 3842700 | AV7: 199752 | AW7: -165402 | AX7: 265303 | AY7: 4473157 | AZ7: 4921639 | BA7: -448482 | BE7: -448482 | BF7: 103800 | BH7: 277200 | BI7: 3367200 | BL7: 94500 | BN7: 3842700 | BW7: 153935 | CA7: 1150 | CC7: 44347 | CI7: 320 | CM7: 11070 | CN7: 0 | CO7: 46800 | CP7: 0 | CQ7: 82961 | CR7: 18028 | CS7: 34553 | CT7: 6340 | CV7: 0 | EC7: -112473 | EG7: -85875 | EI7: 32946 | FG7: 2277186 | FH7: 530957 | FI7: 2113496 | FJ7: 35288 | FK7: 1982292 | FT7: 512 | FV7: 14698 | FX7: 23044 | FY7: 6406 | FZ7: 14464 | GA7: 4237 | GD7: 250150 | GE7: 128988 | GF7: 78467 | GG7: 484622 | GH7: 14817 | GI7: 55290 | GK7: 964719 | GL7: 8892 | GM7: 832500 | GN7: 42012 | GO7: 15529 | GS7: 1877986 | GW7: -695336 | GY7: 1182650 | GZ7: 461503 | HC7: 721147 | HD7: 1182650 | HF7: -697836 | HG7: 70000 | HI7: 0 | HK7: 77864 | HL7: 48001 | HM7: 125865 | HN7: -125865 | HT7: 2.00 | HU7: 923006 | HV7: 1960 | HW7: 0 | HX7: 1659 | HY7: 10275 | HZ7: 28082 | IA7: 0 | IB7: 0 | IC7: 605 | IE7: 1896 | IF7: 4806 | IG7: 2768 | IH7: 12846 | II7: 403 | IJ7: 2199 | IL7: 7304 | IM7: 74803 | IN7: 0 | IO7: 77 | IP7: 126 | IQ7: 2292 | IR7: 0 | IS7: 0 | IT7: 2495 | IU7: 96587 | IV7: 0 | IW7: 76022 | IX7: 465197 | IY7: 773899 | IZ7: 0 | JA7: 0 | JB7: 20893 | JD7: 53088 | JE7: 92380 | JF7: 52609 | JG7: 267761 | JH7: 11966 | JI7: 45070 | JK7: 321714 | JL7: 2277186 | JM7: 0 | JN7: 5471 | JO7: 7728 | JP7: 84201 | JQ7: 0 | JR7: 0 | JS7: 97400 | KF7: 45 | KG7: 69 | KH7: 31 | KI7: 26 | KJ7: 44 | KK7: 17 | KL7: 18 | KM7: 30 | KN7: 11 | KO7: 1 | KP7: 0 | KQ7: 0 | KR7: 1 | KS7: 0 | KT7: 0 | KU7: 1 | KV7: 0 | KW7: 0 | KX7: 0 | KY7: 0 | KZ7: 0 | LA7: 0 | LB7: 0 | LC7: 0 | LD7: 1 | LE7: 0 | LF7: 0 | LG7: 0 | LH7: 0
A8: 206010770 | B8: VALLEY POINTE NURSING & REHABILITATION CENTER | C8: 45292 | D8: 45657 | E8: 366 | F8: In Process | G8: No | H8: Alameda | I8: SNF | J8: Investor Owned | K8: 05 - East Bay | L8: 0421 | M8: 510-538-8464 | N8: 20090 STANTON AVE | O8: CASTRO VALLEY | P8: 94546-5203 | Q8: 1669859567 | R8: ABRAHAM OYLER | S8: Yes | U8: 50 | V8: 50 | W8: 1-59 | X8: 18300 | Y8: 16458 | Z8: 211 | AA8: 289 | AB8: 283 | AC8: 6837 | AD8: 2905 | AE8: 743 | AF8: 5422 | AI8: 57 | AJ8: 494 | AK8: Skilled Nursing Care Only | AL8: 16458 | AU8: 16018252 | AV8: 4508687 | AW8: 7962824 | AX8: 7497 | AY8: 12571612 | AZ8: 11078706 | BA8: 1492906 | BB8: -1 | BE8: 1492905 | BF8: 8546250 | BG8: 3631250 | BH8: 407700 | BI8: 3202562 | BL8: 32650 | BM8: 197840 | BN8: 16018252 | BW8: 3284577 | BY8: 1202215 | CC8: 20831 | CI8: 1064 | CM8: 0 | CN8: 0 | CO8: 1468950 | CP8: 0 | CQ8: 1184900 | CR8: 337800 | CS8: 1221540 | CT8: 216183 | CV8: 79314 | EC8: 3942638 | EE8: 2755681 | EG8: 93054 | EI8: 1163416 | EO8: 8035 | FG8: 4990167 | FH8: 1519213 | FI8: 4569326 | FJ8: 192546 | FK8: 4177339 | FV8: 570165 | FW8: 484 | FX8: 374108 | FY8: 82195 | FZ8: 276978 | GA8: 92695 | GC8: 41104 | GD8: 424838 | GE8: 233937 | GF8: 67037 | GG8: 682023 | GH8: 81802 | GI8: 113630 | GJ8: 110979 | GK8: 2590348 | GL8: 86274 | GM8: 695861 | GN8: 58972 | GO8: 13398 | GQ8: 6815 | GR8: 297724 | GS8: 17821868 | GU8: 460238 | GY8: 18282106 | GZ8: 1427627 | HC8: 16854479 | HD8: 18282106 | HE8: 15679963 | HI8: 0 | HK8: 789800 | HL8: 216862 | HM8: 1006662 | HN8: -546424 | HT8: 0.00 | HU8: 0 | HV8: 1841 | HW8: 0 | HX8: 17002 | HY8: 14186 | HZ8: 40124 | IA8: 0 | IB8: 0 | IC8: 0 | ID8: 9615 | IE8: 2177 | IF8: 7969 | IG8: 3727 | IH8: 15460 | II8: 2009 | IJ8: 3957 | IK8: 1694 | IL8: 17198 | IM8: 136959 | IN8: 0 | IO8: 18 | IP8: 635 | IQ8: 994 | IR8: 0 | IS8: 0 | IT8: 1647 | IU8: 188093 | IV8: 0 | IW8: 920646 | IX8: 603445 | IY8: 1048350 | IZ8: 0 | JA8: 0 | JB8: 0 | JC8: 583473 | JD8: 53989 | JE8: 143127 | JF8: 57525 | JG8: 337339 | JH8: 63931 | JI8: 62862 | JJ8: 87106 | JK8: 840281 | JL8: 4990167 | JM8: 0 | JN8: 1915 | JO8: 47698 | JP8: 38996 | JQ8: 0 | JR8: 0 | JS8: 88609 | JY8: 9615 | KE8: 583473 | KF8: 83 | KG8: 143 | KH8: 49 | KI8: 52 | KJ8: 96 | KK8: 26 | KL8: 24 | KM8: 39 | KN8: 15 | KO8: 1 | KP8: 0 | KQ8: 0 | KR8: 1 | KS8: 0 | KT8: 0 | KU8: 1 | KV8: 0 | KW8: 0 | KX8: 0 | KY8: 0 | KZ8: 0 | LA8: 0 | LB8: 0 | LC8: 0 | LD8: 1 | LE8: 0 | LF8: 0 | LG8: 0 | LH8: 0
A9: 206010774 | B9: EAST BAY POST ACUTE | C9: 45292 | D9: 45657 | E9: 366 | F9: In Process | G9: No | H9: Alameda | I9: SNF | J9: Investor Owned | K9: 05 - East Bay | L9: 0421 | M9: 510-537-1234 | N9: 20259 LAKE CHABOT ROAD | O9: CASTRO VALLEY | P9: 94546 | Q9: 1811366586 | R9: ABRAHAM OYLER | S9: Yes | U9: 91 | V9: 91 | W9: 60-99 | X9: 33306 | Y9: 27963 | Z9: 196.98 | AA9: 237 | AB9: 229 | AC9: 3148 | AD9: 4058 | AE9: 1712 | AF9: 18400 | AH9: 304 | AI9: 14 | AJ9: 327 | AK9: Skilled Nursing Care Only | AL9: 27963 | AU9: 23460125 | AV9: 3035336 | AW9: 12801163 | AX9: 15632 | AY9: 13709930 | AZ9: 15182185 | BA9: -1472255 | BB9: -1 | BE9: -1472256 | BF9: 3935000 | BG9: 4643575 | BH9: 1278550 | BI9: 13103550 | BK9: 256850 | BL9: 10450 | BM9: 232150 | BN9: 23460125 | BW9: 1525949 | BY9: 1376690 | CA9: 8370 | CC9: 31280 | CG9: 89222 | CI9: 3825 | CM9: 1053 | CN9: 0 | CO9: 1086450 | CP9: 245750 | CQ9: 898150 | CR9: 346050 | CS9: 286778 | CT9: 123553 | CV9: 47552 | EC9: 1574153 | EE9: 3094045 | EG9: 1211957 | EI9: 6687788 | EM9: 112214 | EO9: 121006 | FG9: 6178909 | FH9: 1646683 | FI9: 7356593 | FJ9: 250901 | FK9: 6252908 | FT9: 725 | FV9: 505726 | FX9: 317222 | FY9: 73737 | FZ9: 180763 | GA9: 61383 | GC9: 102406 | GD9: 396923 | GE9: 646056 | GF9: 139661 | GG9: 986448 | GH9: 153629 | GI9: 141048 | GJ9: 131103 | GK9: 3257072 | GL9: 247707 | GM9: 771882 | GN9: 113359 | GO9: 18685 | GQ9: 12403 | GR9: 671339 | GS9: 2564233 | GU9: 1057209 | GV9: 22403 | GX9: 90000 | GY9: 3733845 | GZ9: 1935251 | HC9: 1798594 | HD9: 3733845 | HE9: 784179 | HI9: 0 | HK9: 1122373 | HL9: 662959 | HM9: 1785332 | HN9: -728123 | HT9: 0.00 | HU9: 0 | HV9: 2057 | HW9: 0 | HX9: 14032 | HY9: 34470 | HZ9: 50905 | IA9: 0 | IB9: 0 | IC9: 0 | ID9: 6426 | IE9: 3094 | IF9: 24857 | IG9: 1914 | IH9: 18269 | II9: 3504 | IJ9: 4420 | IK9: 2042 | IL9: 14790 | IM9: 180780 | IN9: 0 | IO9: 9 | IP9: 4107 | IQ9: 11941 | IR9: 0 | IS9: 0 | IT9: 16057 | IU9: 185296 | IV9: 0 | IW9: 768691 | IX9: 1533784 | IY9: 1394163 | IZ9: 0 | JA9: 0 | JB9: 0 | JC9: 412672 | JD9: 79286 | JE9: 484232 | JF9: 37150 | JG9: 435812 | JH9: 116433 | JI9: 98351 | JJ9: 97131 | JK9: 535908 | JL9: 6178909 | JM9: 0 | JN9: 844 | JO9: 275092 | JP9: 461730 | JQ9: 0 | JR9: 0 | JS9: 737666 | JY9: 6426 | KE9: 412672 | KF9: 101 | KG9: 217 | KH9: 40 | KI9: 64 | KJ9: 144 | KK9: 25 | KL9: 31 | KM9: 65 | KN9: 14 | KO9: 1 | KP9: 0 | KQ9: 0 | KR9: 0 | KS9: 1 | KT9: 0 | KU9: 1 | KV9: 0 | KW9: 0 | KX9: 0 | KY9: 0 | KZ9: 0 | LA9: 0 | LB9: 0 | LC9: 0 | LD9: 1 | LE9: 0 | LF9: 0 | LG9: 0 | LH9: 0
A10: 206010797 | B10: FREMONT HEALTHCARE CENTER | C10: 45292 | D10: 45657 | E10: 366 | F10: In Process | G10: No | H10: Alameda | I10: SNF | J10: Investor Owned | K10: 05 - East Bay | L10: 0421 | M10: 510-792-3743 | N10: 39022 PRESIDIO WAY | O10: FREMONT | P10: 94538 | Q10: 1194120600 | R10: ESPENITO CARAMBA | S10: Yes | T10: NATIONAL SENIOR CARE, INC. | U10: 115 | V10: 115 | W10: 100+ | X10: 42090 | Y10: 38410 | Z10: 153.92 | AA10: 189 | AB10: 185 | AC10: 5092 | AD10: 2703 | AE10: 3202 | AF10: 26572 | AI10: 203 | AJ10: 638 | AK10: Skilled Nursing Care Only | AL10: 38410 | AU10: 19179169 | AV10: 4081339 | AW10: 6005857 | AX10: 36 | AY10: 17254687 | AZ10: 17762298 | BA10: -507611 | BB10: 12426 | BE10: -495185 | BF10: 2765881 | BG10: 1498811 | BH10: 1696192 | BI10: 12857721 | BL10: 44849 | BM10: 315715 | BN10: 19179169 | BW10: 2862729 | BY10: 1080795 | CA10: 66382 | CC10: 67311 | CI10: -614 | CK10: 4736 | CM10: 0 | CN10: 0 | CO10: 1563808 | CP10: 0 | CQ10: 1856685 | CR10: 90760 | CS10: 481276 | CT10: 78161 | CV10: 10649 | EC10: 290624 | EE10: 1085957 | EG10: 277199 | EI10: 4237702 | EO10: 114372 | FE10: 3 | FG10: 6546468 | FH10: 2195567 | FI10: 9020263 | FJ10: 188957 | FK10: 8120481 | FT10: 103356 | FV10: 381581 | FW10: 7714 | FX10: 463978 | FY10: 9551 | FZ10: 194808 | GA10: 78717 | GC10: 38796 | GD10: 533629 | GE10: 542390 | GF10: 137069 | GG10: 1109699 | GH10: 171577 | GI10: 152793 | GK10: 3842154 | GL10: 95884 | GM10: 1068065 | GN10: 165461 | GO10: 146720 | GP10: 52161 | GR10: 345714 | GS10: 2366546 | GU10: 733156 | GV10: 41255 | GW10: 354549 | GY10: 3495506 | GZ10: 1584822 | HA10: 267943 | HC10: 1642741 | HD10: 3495506 | HG10: -1170561 | HI10: 0 | HJ10: 2327088 | HK10: 1062394 | HL10: 1120546 | HM10: 4510028 | HN10: -3776872 | HT10: 0.00 | HU10: 0 | HV10: 8586 | HW10: 0 | HX10: 21495 | HY10: 19717 | HZ10: 63693 | IA10: 0 | IB10: 0 | IC10: 5253 | IE10: 3649 | IF10: 18054 | IG10: 3782 | IH10: 20520 | II10: 3806 | IJ10: 4405 | IL10: 18476 | IM10: 191436 | IN10: 0 | IO10: 250 | IP10: 1454 | IQ10: 35519 | IR10: 0 | IS10: 0 | IT10: 37223 | IU10: 547110 | IV10: 0 | IW10: 1193352 | IX10: 895583 | IY10: 1830586 | IZ10: 0 | JA10: 0 | JB10: 190987 | JD10: 91208 | JE10: 365914 | JF10: 78713 | JG10: 488528 | JH10: 129120 | JI10: 110287 | JK10: 625080 | JL10: 6546468 | JM10: 0 | JN10: 19038 | JO10: 99611 | JP10: 1587118 | JQ10: 0 | JR10: 0 | JS10: 1705767 | KF10: 135 | KG10: 168 | KH10: 106 | KI10: 80 | KJ10: 108 | KK10: 58 | KL10: 47 | KM10: 67 | KN10: 31 | KO10: 1 | KP10: 0 | KQ10: 0 | KR10: 0 | KS10: 0 | KT10: 1 | KU10: 1 | KV10: 0 | KW10: 0 | KX10: 0 | KY10: 0 | KZ10: 0 | LA10: 0 | LB10: 0 | LC10: 0 | LD10: 1 | LE10: 0 | LF10: 0 | LG10: 0 | LH10: 0
A11: 206010798 | B11: DRIFTWOOD HEALTHCARE CENTER - HAYWARD | C11: 45292 | D11: 45657 | E11: 366 | F11: In Process | G11: No | H11: Alameda | I11: SNF | J11: Investor Owned | K11: 05 - East Bay | L11: 0421 | M11: 510-785-2880 | N11: 19700 HESPERIAN BLVD. | O11: HAYWARD | P11: 94541 | Q11: 1871881557 | R11: ERIKA AGAPAY | S11: Yes | T11: NATIONAL SENIOR CARE, INC. | U11: 88 | V11: 88 | W11: 60-99 | X11: 32208 | Y11: 28051 | Z11: 146.89 | AA11: 102 | AB11: 99 | AC11: 1682 | AD11: 2601 | AE11: 3876 | AF11: 19415 | AI11: 316 | AJ11: 161 | AK11: Mixed Care | AL11: 19818 | AP11: 8233 | AU11: 19837459 | AV11: 4546424 | AW11: 9617409 | AX11: 34 | AY11: 14766508 | AZ11: 15608435 | BA11: -841927 | BB11: 17057 | BE11: -824870 | BF11: 1372360 | BG11: 1767991 | BH11: 2853116 | BI11: 13357878 | BL11: 412257 | BM11: 73857 | BN11: 9346330 | BR11: 10491129 | BW11: 2171305 | BY11: 1785889 | CA11: 213406 | CC11: 376037 | CI11: -948 | CK11: 735 | CM11: 0 | CN11: -948 | CO11: 2411448 | CP11: 0 | CQ11: 985320 | CR11: 786880 | CS11: 300075 | CT11: 56003 | CV11: 7646 | EC11: 1159419 | EE11: 1681013 | EG11: 1387305 | EI11: 5407602 | EO11: -17934 | FE11: 4 | FG11: 6490283 | FH11: 2179252 | FI11: 6938900 | FJ11: 181703 | FK11: 4793994 | FO11: 2977225 | FT11: 224778 | FU11: 515 | FV11: 410117 | FW11: 508393 | FX11: 155920 | FY11: 126543 | FZ11: 103390 | GA11: 50765 | GC11: 57038 | GD11: 407385 | GE11: 466566 | GF11: 257684 | GG11: 1000999 | GH11: 91402 | GI11: 152511 | GK11: 3035647 | GL11: 121475 | GM11: 61842 | GN11: 97354 | GO11: 190989 | GP11: 20769 | GR11: 295134 | GS11: 3182386 | GU11: 418039 | GV11: -466215 | GW11: 268637 | GY11: 3402847 | GZ11: 2241315 | HA11: 361263 | HC11: 800269 | HD11: 3402847 | HG11: -180466 | HI11: 0 | HJ11: 722119 | HK11: 773758 | HL11: 1102035 | HM11: 2597912 | HN11: -2179873 | HT11: 0.00 | HU11: 0 | HV11: 7341 | HW11: 0 | HX11: 13810 | HY11: 42235 | HZ11: 54862 | IA11: 0 | IB11: 0 | IC11: 4117 | IF11: 13141 | IG11: 8582 | IH11: 17805 | II11: 1974 | IJ11: 5509 | IL11: 14593 | IM11: 183969 | IN11: 0 | IO11: 711 | IP11: 5287 | IQ11: 16984 | IR11: 0 | IS11: 8632 | IT11: 31614 | IU11: 492641 | IV11: 0 | IW11: 762510 | IX11: 1934178 | IY11: 1516138 | IZ11: 0 | JA11: 0 | JB11: 157813 | JE11: 301428 | JF11: 166228 | JG11: 438580 | JH11: 70006 | JI11: 112004 | JK11: 538757 | JL11: 6490283 | JM11: 0 | JN11: 50683 | JO11: 286842 | JP11: 659136 | JQ11: 0 | JR11: 431600 | JS11: 1428261 | KF11: 229 | KG11: 254 | KH11: 197 | KI11: 162 | KJ11: 178 | KK11: 140 | KL11: 67 | KM11: 75 | KN11: 58 | KO11: 1 | KP11: 0 | KQ11: 0 | KR11: 0 | KS11: 1 | KT11: 0 | KU11: 1 | KV11: 0 | KW11: 0 | KX11: 0 | KY11: 1 | KZ11: 0 | LA11: 0 | LB11: 0 | LC11: 0 | LD11: 1 | LE11: 0 | LF11: 0 | LG11: 0 | LH11: 0
A12: 206010806 | B12: HAYWARD HEALTHCARE AND WELLNESS CENTER | C12: 45170 | D12: 45535 | E12: 366 | F12: In Process | G12: No | H12: Alameda | I12: SNF | J12: Investor Owned | K12: 05 - East Bay | L12: 0421 | M12: 510-783-4811 | N12: 1805 WEST STREET | O12: HAYWARD | P12: 94545 | Q12: 1639401227 | R12: DATT, LALEEN | S12: Yes | U12: 99 | V12: 99 | W12: 60-99 | X12: 36234 | Y12: 33904 | Z12: 93.57 | AA12: 419 | AB12: 392 | AC12: 3882 | AE12: 2704 | AF12: 21971 | AG12: 3849 | AI12: 1019 | AJ12: 479 | AK12: Skilled Nursing Care Only | AL12: 33904 | AU12: 16600635 | AV12: 6559432 | AW12: 7070998 | AY12: 16089069 | AZ12: 16118662 | BA12: -29593 | BB12: 420112 | BC12: 12590 | BE12: 377929 | BF12: 3493800 | BH12: 881114 | BI12: 8272082 | BJ12: 3463527 | BL12: 334669 | BM12: 155443 | BN12: 16600635 | BW12: 2931962 | CA12: 48067 | CC12: 794131 | CE12: 2779125 | CI12: 5259 | CK12: 888 | CM12: 23087 | CN12: 53078 | CO12: 2269157 | CP12: 0 | CQ12: 1634344 | CR12: 718586 | CS12: 1279240 | CT12: 387798 | CV12: 194142 | DY12: 1719 | EC12: 1548086 | EG12: 141468 | EI12: 2148492 | EK12: 3213367 | EO12: 17866 | FG12: 7538249 | FH12: 1767568 | FI12: 6812845 | FJ12: 303529 | FK12: 6769717 | FT12: 10244 | FU12: 25197 | FV12: 496492 | FX12: 417112 | FY12: 107870 | FZ12: 415710 | GA12: 59616 | GC12: 93041 | GD12: 812649 | GE12: 369179 | GF12: 113211 | GG12: 964388 | GH12: 164316 | GI12: 245111 | GJ12: 130957 | GK12: 3034114 | GL12: 53783 | GM12: 1499297 | GN12: 96977 | GO12: 15738 | GQ12: 1189 | GR12: 222754 | GS12: 8428310 | GU12: 132901 | GV12: 386698 | GW12: 9883535 | GY12: 18831444 | GZ12: 14033450 | HC12: 4797994 | HD12: 18831444 | HE12: 4461513 | HG12: 1057558 | HI12: 0 | HJ12: 3400 | HK12: 498595 | HL12: 404342 | HM12: 906337 | HN12: -773436 | HT12: 0.01 | HU12: 140334.5 | HV12: 2024 | HW12: 0 | HX12: 13588 | HY12: 29202 | HZ12: 70485 | IA12: 0 | IB12: 0 | IC12: 6281 | ID12: 12201 | IE12: 5919 | IF12: 13345 | IG12: 4295 | IH12: 22928 | II12: 4289 | IJ12: 8374 | IK12: 2220 | IL12: 18411 | IM12: 213562 | IN12: 0 | IO12: 25 | IP12: 2001 | IQ12: 7656 | IR12: 0 | IS12: 0 | IT12: 9682 | IU12: 186678 | IV12: 0 | IW12: 710181 | IX12: 1393934 | IY12: 2048151 | IZ12: 0 | JA12: 0 | JB12: 294789 | JC12: 599531 | JD12: 156259 | JE12: 246518 | JF12: 77840 | JG12: 538370 | JH12: 133562 | JI12: 197344 | JJ12: 111261 | JK12: 843831 | JL12: 7538249 | JM12: 0 | JN12: 1918 | JO12: 108340 | JP12: 300178 | JQ12: 0 | JR12: 0 | JS12: 410436 | JY12: 12201 | KE12: 599531 | KF12: 156 | KG12: 254 | KH12: 93 | KI12: 80 | KJ12: 132 | KK12: 51 | KL12: 47 | KM12: 76 | KN12: 31 | KO12: 1 | KP12: 0 | KQ12: 0 | KR12: 0 | KS12: 1 | KT12: 0 | KU12: 1 | KV12: 0 | KW12: 0 | KX12: 0 | KY12: 0 | KZ12: 0 | LA12: 0 | LB12: 0 | LC12: 0 | LD12: 1 | LE12: 0 | LF12: 0 | LG12: 0 | LH12: 0
